
try (final TestAcloseable something = new TestAcloseable(false, true);) {
    _ASSERT_NOT_NULL = something;
    something.doRiskyThings();
} catch (Throwable err) {
    System.out.println("Catching some domain specific error here...");
}
======================>======<======================
======================>After<======================
try {
    java.lang.RuntimeException _Scope_Runtime_Exception;
    final TestAcloseable something = new TestAcloseable(false, true);
    try {
        _ASSERT_NOT_NULL = something;
        something.doRiskyThings();
    } catch (java.lang.Throwable _nest_catch_throwable) {
        _Scope_Runtime_Exception.addSuppressed(_nest_catch_throwable);
        if (something != null) {
            try {
                something.close();
                something = null;
            } catch (java.lang.Throwable _inner_inner_throwable_suppressed) {
                _Scope_Runtime_Exception.addSuppressed(_inner_inner_throwable_suppressed);
            } finally {
            }
        }
        throw _nest_catch_throwable;  <<<<<<<<<<<<<<<<<<<----------  2017-04-27 Thu 12:12 PM  <Move this>
    } finally {
        if (something != null) {
            try {
                something.close();
                something = null;
            } catch (java.lang.Throwable _inner_inner_throwable_suppressed) {
                _Scope_Runtime_Exception.addSuppressed(_inner_inner_throwable_suppressed);
            } finally {
                                             <<--- To here.  I think that's the only way to do it
            }
        }
    }
} catch (Throwable err) {
    System.out.println("Catching some domain specific error here...");
}
======================>======<======================
Loading compiled class: SampleSomethingClass
Performing work normally...
Throwing exception on close()...
Catching some domain specific error here...

java.lang.AssertionError: Expected exception: java.lang.RuntimeException

	at org.junit.internal.runners.statements.ExpectException.evaluate(ExpectException.java:32)
	at org.junit.runners.ParentRunner.runLeaf(ParentRunner.java:325)
	at org.junit.runners.BlockJUnit4ClassRunner.runChild(BlockJUnit4ClassRunner.java:78)
	at org.junit.runners.BlockJUnit4ClassRunner.runChild(BlockJUnit4ClassRunner.java:57)
	at org.junit.runners.ParentRunner$3.run(ParentRunner.java:290)
	at org.junit.runners.ParentRunner$1.schedule(ParentRunner.java:71)
	at org.junit.runners.ParentRunner.runChildren(ParentRunner.java:288)
	at org.junit.runners.ParentRunner.access$000(ParentRunner.java:58)
	at org.junit.runners.ParentRunner$2.evaluate(ParentRunner.java:268)
	at org.junit.runners.ParentRunner.run(ParentRunner.java:363)
	at org.junit.runner.JUnitCore.run(JUnitCore.java:137)
	at com.intellij.junit4.JUnit4IdeaTestRunner.startRunnerWithArgs(JUnit4IdeaTestRunner.java:68)
	at com.intellij.rt.execution.junit.IdeaTestRunner$Repeater.startRunnerWithArgs(IdeaTestRunner.java:51)
	at com.intellij.rt.execution.junit.JUnitStarter.prepareStreamsAndStart(JUnitStarter.java:242)
	at com.intellij.rt.execution.junit.JUnitStarter.main(JUnitStarter.java:70)


Process finished with exit code 255
